Workbook
Name _Toc179793326: Ratios!$B$13

Sheet Introducción de datos
B6: Plan de inversiones iniciales
B7: Concepto | C7: Importe | D7: % | E7: % anual de amortización | F7: Amortización anual | G7: Amortización mensual
B8: Inmovilizado material | C8: =SUM(C9:C14) -> 15100 | D8: =C8/C27 -> 0.48033964 | F8: =SUM(F9:F14) -> 2053 | G8: =SUM(G9:G14) -> 171.08333
B9: Edificios, locales y terrenos | C9: 0 | D9: =C9/$C$27 -> 0 | E9: 0.02 | F9: =C9*E9 -> 0 | G9: =F9/12 -> 0
B10: Instalaciones | C10: 2200 | D10: =C10/$C$27 -> 0.069983258 | E10: 0.1 | F10: =C10*E10 -> 220 | G10: =F10/12 -> 18.333333
B11: Elementos de transporte | C11: 0 | D11: =C11/$C$27 -> 0 | E11: 0.16 | F11: =C11*E11 -> 0 | G11: =F11/12 -> 0
B12: Mobiliario y herramientas de oficina | C12: 900 | D12: =C12/$C$27 -> 0.028629515 | E12: 0.12 | F12: =C12*E12 -> 108 | G12: =F12/12 -> 9
B13: Maquinaria, herramientas | C13: 8500 | D13: =C13/$C$27 -> 0.27038986 | E13: 0.1 | F13: =C13*E13 -> 850 | G13: =F13/12 -> 70.833333
B14: Equipamientos informáticos | C14: 3500 | D14: =C14/$C$27 -> 0.111337 | E14: 0.25 | F14: =C14*E14 -> 875 | G14: =F14/12 -> 72.916667
B15: Inmovilizado inmaterial | C15: =SUM(C16:C22) -> 10850 | D15: =C15/C27 -> 0.3451447
B16: Derechos de traspaso | C16: 0 | D16: =C16/$C$27 -> 0
B17: Marcas y patentes | C17: 650 | D17: =C17/$C$27 -> 0.020676872
B18: Depósitos y fianzas | D18: =C18/$C$27 -> 0
B19: Estudios previos | C19: 1200 | D19: =C19/$C$27 -> 0.038172686
B20: Concesiones administrativas o explotación | C20: 0 | D20: =C20/$C$27 -> 0
B21: Aplicaciones informáticas | C21: 9000 | D21: =C21/$C$27 -> 0.28629515
B22: Otros gastos | C22: 0 | D22: =C22/$C$27 -> 0
B23: Circulante | C23: =SUM(C24:C26) -> 5486.09 | D23: =C23/C27 -> 0.17451566
B24: Existencias | C24: 5486.09 | D24: =C24/$C$27 -> 0.17451566
B25: Otros gastos iniciales | C25: 0 | D25: =C25/$C$27 -> 0
B26: Provisión de fondos | C26: 0 | D26: =C26/$C$27 -> 0
B27: Total | C27: =C23+C15+C8 -> 31436.09 | D27: 1
B30: Costes generales y operativos
B31: Concepto | C31: Anual | D31: Mensual
B32: Alquileres | C32: =C33+C34 -> 4800 | D32: =D33+D34 -> 400
B33: Alquiler local | C33: =D33*12 -> 0 | D33: 0
B34: Renting vehículo | C34: =D34*12 -> 4800 | D34: 400
B35: Suministros (agua, luz, gas,…) | C35: =SUM(C36:C37) -> 1080 | D35: =SUM(D36:D37) -> 90
B36: Agua y luz | C36: =D36*12 -> 360 | D36: 30
B37: Teléfono e internet | C37: =D37*12 -> 720 | D37: 60
B38: Servicios externos | C38: =SUM(C39:C44) -> 9360 | D38: =SUM(D39:D44) -> 780
B39: Limpieza y/o seguridad | C39: =D39*12 -> 0 | D39: 0
B40: Mantenimiento equipos/maquinaria | C40: =D40*12 -> 1200 | D40: 100
B41: Seguros | C41: =D41*12 -> 600 | D41: 50
B42: Marketing: promoción y comunicación | C42: =D42*12 -> 3000 | D42: 250
B43: Serv. profesionales (asesoría-gestoría, ..) | C43: =D43*12 -> 1440 | D43: 120
B44: Alquiler de software y alojamiento web | C44: =D44*12 -> 3120 | D44: 260
B45: Otros costes | C45: =SUM(C46:C50) -> 4080 | D45: =SUM(D46:D50) -> 340
B46: Material de oficina | C46: =D46*12 -> 300 | D46: 25
B47: Gastos constitución empresa | C47: =D47*12 -> 0 | D47: 0
...

Sheet Fuentes de financiación
B8: Plan de financiación
B9: Concepto | C9: Importe | D9: %
B10: Ahorros personales | C10: =C16-C12 -> 1436.09 | D10: =C10/$C$16 -> 0.045682844
B11: Ahorros de la familia y/o amigos | C11: 0 | D11: =C11/$C$16 -> 0
B12: Préstamos o créditos bancarios | C12: =C22 -> 30000 | D12: =C12/$C$16 -> 0.95431716
B13: Créditos de proveedores | C13: 0 | D13: =C13/$C$16 -> 0
B14: Selección de clientes | C14: 0 | D14: =C14/$C$16 -> 0
B15: Otros | C15: 0 | D15: =C15/$C$16 -> 0
B16: Total | C16: ='Introducción de datos'!C27 -> 31436.09 | D16: =C16/$C$16 -> 1
B20: Origen | C20: Importe en €
B21: Fondos propios | C21: =C10+C11 -> 1436.09
B22: Préstamo MicroBank* | C22: 30000
B23: Otros | C23: =C13+C14+C15 -> 0
B24: Total | C24: =C16 -> 31436.09
B25: *Préstamo MicroBank
B26: Importe: | C26: =C22 -> 30000
B27: Plazo amortización (cuotas mensuales) | C27: =6*12 -> 72
B28: Carencia (meses) | C28: 6
B30: Fecha inicio préstamo | C30: 46266

Sheet Cuadro amortización crédito
A8: Préstamo | D8: Fecha inicio | E8: ='Fuentes de financiación'!C30 -> 46266 | F8: Cuotas | G8: =G9*12 -> 72
A9: Capital | C9: ='Fuentes de financiación'!C26 -> 30000 | D9: Tipo Interés | E9: 0.069 | F9: Años | G9: 6 | H9: Carencia meses | I9: 6
H10: =SUM(E13:E24) -> 2282.7618 | I10: =+F13-H10 -> 27717.238
A11: Mes | B11: Fecha | C11: Cuota | D11: Interés | E11: Amort. Cap. | F11: Capital inicial | G11: Capital final | H11: Pendiente C/P | I11: Pendiente L/P
F12: =C9 -> 30000 | H12: =SUM(E13:E24) -> 2282.7618 | I12: =SUM(E25:E84) -> 27717.238
A13: 1 | B13: ='Cuadro amortización crédito'!E8 -> 46266 | C13: =IF(A13<=$I$9,D13,-PMT($E$9/12,$G$9*12-$I$9,$C$9,0,0)) -> 172.5 | D13: =+$E$9/12*F13 -> 172.5 | E13: =+C13-D13 -> 0 | F13: =+C9 -> 30000 | G13: =+F13-E13 -> 30000 | H13: =SUM(E14:E25) -> 2670.9155 | I13: =SUM(E26:E85) -> 27329.084
A14: 2 | B14: =EDATE(B13,1) -> 46296 | C14: =IF(A14<=$I$9,D14,-PMT($E$9/12,$G$9*12-$I$9,$C$9,0,0)) -> 172.5 | D14: =+$E$9/12*F14 -> 172.5 | E14: =+C14-D14 -> 0 | F14: =+G13 -> 30000 | G14: =+F14-E14 -> 30000 | H14: =SUM(E15:E26) -> 3061.301 | I14: =SUM(E27:E86) -> 26938.699
A15: 3 | B15: =EDATE(B14,1) -> 46327 | C15: =IF(A15<=$I$9,D15,-PMT($E$9/12,$G$9*12-$I$9,$C$9,0,0)) -> 172.5 | D15: =+$E$9/12*F15 -> 172.5 | E15: =+C15-D15 -> 0 | F15: =+G14 -> 30000 | G15: =+F15-E15 -> 30000 | H15: =SUM(E16:E27) -> 3453.9313 | I15: =SUM(E28:E87) -> 26546.069
A16: 4 | B16: =EDATE(B15,1) -> 46357 | C16: =IF(A16<=$I$9,D16,-PMT($E$9/12,$G$9*12-$I$9,$C$9,0,0)) -> 172.5 | D16: =+$E$9/12*F16 -> 172.5 | E16: =+C16-D16 -> 0 | F16: =+G15 -> 30000 | G16: =+F16-E16 -> 30000 | H16: =SUM(E17:E28) -> 3848.8192 | I16: =SUM(E29:E88) -> 26151.181
A17: 5 | B17: =EDATE(B16,1) -> 46388 | C17: =IF(A17<=$I$9,D17,-PMT($E$9/12,$G$9*12-$I$9,$C$9,0,0)) -> 172.5 | D17: =+$E$9/12*F17 -> 172.5 | E17: =+C17-D17 -> 0 | F17: =+G16 -> 30000 | G17: =+F17-E17 -> 30000 | H17: =SUM(E18:E29) -> 4245.9777 | I17: =SUM(E30:E89) -> 25754.022
A18: 6 | B18: =EDATE(B17,1) -> 46419 | C18: =IF(A18<=$I$9,D18,-PMT($E$9/12,$G$9*12-$I$9,$C$9,0,0)) -> 172.5 | D18: =+$E$9/12*F18 -> 172.5 | E18: =+C18-D18 -> 0 | F18: =+G17 -> 30000 | G18: =+F18-E18 -> 30000 | H18: =SUM(E19:E30) -> 4645.4198 | I18: =SUM(E31:E90) -> 25354.58
A19: 7 | B19: =EDATE(B18,1) -> 46447 | C19: =IF(A19<=$I$9,D19,-PMT($E$9/12,$G$9*12-$I$9,$C$9,0,0)) -> 547.52777 | D19: =+$E$9/12*F19 -> 172.5 | E19: =+C19-D19 -> 375.02777 | F19: =+G18 -> 30000 | G19: =+F19-E19 -> 29624.972 | H19: =SUM(E20:E31) -> 4672.131 | I19: =SUM(E32:E91) -> 24952.841
A20: 8 | B20: =EDATE(B19,1) -> 46478 | C20: =IF(A20<=$I$9,D20,-PMT($E$9/12,$G$9*12-$I$9,$C$9,0,0)) -> 547.52777 | D20: =+$E$9/12*F20 -> 170.34359 | E20: =+C20-D20 -> 377.18418 | F20: =+G19 -> 29624.972 | G20: =+F20-E20 -> 29247.788 | H20: =SUM(E21:E32) -> 4698.9957 | I20: =SUM(E33:E92) -> 24548.792
A21: 9 | B21: =EDATE(B20,1) -> 46508 | C21: =IF(A21<=$I$9,D21,-PMT($E$9/12,$G$9*12-$I$9,$C$9,0,0)) -> 547.52777 | D21: =+$E$9/12*F21 -> 168.17478 | E21: =+C21-D21 -> 379.35299 | F21: =+G20 -> 29247.788 | G21: =+F21-E21 -> 28868.435 | H21: =SUM(E22:E33) -> 4726.0149 | I21: =SUM(E34:E93) -> 24142.42
A22: 10 | B22: =EDATE(B21,1) -> 46539 | C22: =IF(A22<=$I$9,D22,-PMT($E$9/12,$G$9*12-$I$9,$C$9,0,0)) -> 547.52777 | D22: =+$E$9/12*F22 -> 165.9935 | E22: =+C22-D22 -> 381.53427 | F22: =+G21 -> 28868.435 | G22: =+F22-E22 -> 28486.901 | H22: =SUM(E23:E34) -> 4753.1895 | I22: =SUM(E35:E94) -> 23733.711
A23: 11 | B23: =EDATE(B22,1) -> 46569 | C23: =IF(A23<=$I$9,D23,-PMT($E$9/12,$G$9*12-$I$9,$C$9,0,0)) -> 547.52777 | D23: =+$E$9/12*F23 -> 163.79968 | E23: =+C23-D23 -> 383.72809 | F23: =+G22 -> 28486.901 | G23: =+F23-E23 -> 28103.173 | H23: =SUM(E24:E35) -> 4780.5204 | I23: =SUM(E36:E95) -> 23322.652
A24: 12 | B24: =EDATE(B23,1) -> 46600 | C24: =IF(A24<=$I$9,D24,-PMT($E$9/12,$G$9*12-$I$9,$C$9,0,0)) -> 547.52777 | D24: =+$E$9/12*F24 -> 161.59324 | E24: =+C24-D24 -> 385.93453 | F24: =+G23 -> 28103.173 | G24: =+F24-E24 -> 27717.238 | H24: =SUM(E25:E36) -> 4808.0084 | I24: =SUM(E37:E96) -> 22909.23
A25: 13 | B25: =EDATE(B24,1) -> 46631 | C25: =IF(A25<=$I$9,D25,-PMT($E$9/12,$G$9*12-$I$9,$C$9,0,0)) -> 547.52777 | D25: =+$E$9/12*F25 -> 159.37412 | E25: =+C25-D25 -> 388.15365 | F25: =+G24 -> 27717.238 | G25: =+F25-E25 -> 27329.084 | H25: =SUM(E26:E37) -> 4835.6544 | I25: =SUM(E38:E97) -> 22493.43
... A84: 72 | B84: =EDATE(B83,1) -> 48427 | C84: =IF(A84<=$I$9,D84,-PMT($E$9/12,$G$9*12-$I$9,$C$9,0,0)) -> 547.52777 | D84: =+$E$9/12*F84 -> 3.1302856 | E84: =+C84-D84 -> 544.39749 | F84: =+G83 -> 544.39749 | G84: =+F84-E84 -> -1.5347723e-11 | H84: =SUM(E85:E96) -> 0 | I84: =SUM(E97:E156) -> 0

Sheet Personal
C9: Salario base ANUAL por categoría en euros brutos | D9: Salario base MENSUAL por categoría en euros brutos | E9: Costes sociales en porcentaje (Normal 30%) | F9: Costes sociales mensuales | G9: Incremento estimado anual %) | H9: Coste total anual | I9: Coste total mensual
B10: Gerente (autónomo) | C10: =D10*12 -> 18000 | D10: 1500 | E10: =325*12 -> 3900 | F10: =E10/12 -> 325 | H10: =E10+C10 -> 21900 | I10: =H10/12 -> 1825
B11: Empleados asalariados | C11: =C10 -> 18000 | D11: =C11/12 -> 1500 | E11: =C11*0.3 -> 5400 | F11: =E11/12 -> 450 | H11: =E11+C11 -> 23400 | I11: =H11/12 -> 1950
B14: Costes de personal (personas)
B15: Concepto | C15: Saldo
C16: Mes 1 | D16: Mes 2 | E16: Mes 3 | F16: Mes 4 | G16: Mes 5 | H16: Mes 6 | I16: Mes 7 | J16: Mes 8 | K16: Mes 9 | L16: Mes 10 | M16: Mes 11 | N16: Mes 12 | O16: Mes 13 | P16: Mes 14 | Q16: Mes 15 | R16: Mes 16 | S16: Mes 17 | T16: Mes 18 | U16: Mes 19 | V16: Mes 20 | W16: Mes 21 | X16: Mes 22 | Y16: Mes 23 | Z16: Mes 24 | AA16: Mes 25 | AB16: Mes 26 | AC16: Mes 27 | AD16: Mes 28 | AE16: Mes 29 | AF16: Mes 30 | AG16: Mes 31 | AH16: Mes 32 | AI16: Mes 33 | AJ16: Mes 34 | AK16: Mes 35 | AL16: Mes 36
B17: Costes de personal | C17: =C29 -> 46266 | D17: =EDATE(C17,1) -> 46296 | E17: =EDATE(D17,1) -> 46327 | F17: =EDATE(E17,1) -> 46357 | G17: =EDATE(F17,1) -> 46388 | H17: =EDATE(G17,1) -> 46419 | I17: =EDATE(H17,1) -> 46447 | J17: =EDATE(I17,1) -> 46478 | K17: =EDATE(J17,1) -> 46508 | ... AL17: =EDATE(AK17,1) -> 47331
B18: Gerente (autónomo) | C18: 1 | D18: 1 | E18: 1 | F18: 1 | G18: 1 | H18: 1 | I18: 1 | J18: 1 | K18: 1 | L18: 1 | M18: 1 | N18: 1 | O18: 1 | P18: 1 | Q18: 1 | R18: 1 | S18: 1 | T18: 1 | U18: 1 | V18: 1 | W18: 1 | X18: 1 | Y18: 1 | Z18: 1 | AA18: 1 | AB18: 1 | AC18: 1 | AD18: 1 | AE18: 1 | AF18: 1 | AG18: 1 | AH18: 1 | AI18: 1 | AJ18: 1 | AK18: 1 | AL18: 1
B19: SS autónomo | C19: 1 | D19: 1 | E19: 1 | F19: 1 | G19: 1 | H19: 1 | I19: 1 | J19: 1 | K19: 1 | L19: 1 | M19: 1 | N19: 1 | O19: 1 | P19: 1 | Q19: 1 | R19: 1 | S19: 1 | T19: 1 | U19: 1 | V19: 1 | W19: 1 | X19: 1 | Y19: 1 | Z19: 1 | AA19: 1 | AB19: 1 | AC19: 1 | AD19: 1 | AE19: 1 | AF19: 1 | AG19: 1 | AH19: 1 | AI19: 1 | AJ19: 1 | AK19: 1 | AL19: 1
B20: Empleados asalariados | G20: 0.5 | H20: 0.5 | I20: 0.5 | J20: 0.5 | K20: 0.5 | L20: 0.5 | M20: 0.5 | N20: 0.5 | O20: 0.5 | P20: 0.5 | Q20: 0.5 | R20: 0.5 | S20: 1 | T20: 1 | U20: 1 | V20: 1 | W20: 1 | X20: 1 | Y20: 1 | Z20: 1 | AA20: 1 | AB20: 1 | AC20: 1 | AD20: 1 | AE20: 1 | AF20: 1 | AG20: 1 | AH20: 1 | AI20: 1 | AJ20: 1 | AK20: 1 | AL20: 1
B21: SS asalariados | G21: 0.5 | H21: 0.5 | I21: 0.5 | J21: 0.5 | K21: 0.5 | L21: 0.5 | M21: 0.5 | N21: 0.5 | O21: 0.5 | P21: 0.5 | Q21: 0.5 | R21: 0.5 | S21: 1 | T21: 1 | U21: 1 | V21: 1 | W21: 1 | X21: 1 | Y21: 1 | Z21: 1 | AA21: 1 | AB21: 1 | AC21: 1 | AD21: 1 | AE21: 1 | AF21: 1 | AG21: 1 | AH21: 1 | AI21: 1 | AJ21: 1 | AK21: 1 | AL21: 1
B22: Costes de personal (UNIDADES) | C22: =C20+C18 -> 1 | D22: =D20+D18 -> 1 | E22: =E20+E18 -> 1 | F22: =F20+F18 -> 1 | G22: =G20+G18 -> 1.5 | H22: =H20+H18 -> 1.5 | I22: =I20+I18 -> 1.5 | J22: =J20+J18 -> 1.5 | ... AL22: =AL20+AL18 -> 2
B26: Costes de personal
B27: Concepto | C27: Saldo
C28: Mes 1 | D28: Mes 2 | E28: Mes 3 | F28: Mes 4 | G28: Mes 5 | H28: Mes 6 | I28: Mes 7 | J28: Mes 8 | K28: Mes 9 | L28: Mes 10 | M28: Mes 11 | N28: Mes 12 | O28: Mes 13 | P28: Mes 14 | Q28: Mes 15 | R28: Mes 16 | S28: Mes 17 | T28: Mes 18 | U28: Mes 19 | V28: Mes 20 | W28: Mes 21 | X28: Mes 22 | Y28: Mes 23 | Z28: Mes 24 | AA28: Mes 25 | AB28: Mes 26 | AC28: Mes 27 | AD28: Mes 28 | AE28: Mes 29 | AF28: Mes 30 | AG28: Mes 31 | AH28: Mes 32 | AI28: Mes 33 | AJ28: Mes 34 | AK28: Mes 35 | AL28: Mes 36
B29: Costes de personal | C29: ='Fuentes de financiación'!C30 -> 46266 | D29: =EDATE(C29,1) -> 46296 | E29: =EDATE(D29,1) -> 46327 | F29: =EDATE(E29,1) -> 46357 | G29: =EDATE(F29,1) -> 46388 | H29: =EDATE(G29,1) -> 46419 | I29: =EDATE(H29,1) -> 46447 | J29: =EDATE(I29,1) -> 46478 | K29: =EDATE(J29,1) -> 46508 | ... AL29: =EDATE(AK29,1) -> 47331
B30: Gerente (autónomo) | C30: =C18*$D$10 -> 1500 | D30: =D18*$D$10 -> 1500 | E30: =E18*$D$10 -> 1500 | F30: =F18*$D$10 -> 1500 | G30: =G18*$D$10 -> 1500 | H30: =H18*$D$10 -> 1500 | I30: =I18*$D$10 -> 1500 | J30: =J18*$D$10 -> 1500 | ... AL30: =AL18*$D$10 -> 1500
B31: SS autónomo | C31: 325 | D31: 325 | E31: 325 | F31: 325 | G31: 325 | H31: 325 | I31: 325 | J31: 325 | K31: 325 | L31: 325 | M31: 325 | N31: 325 | O31: 325 | P31: 325 | Q31: 325 | R31: 325 | S31: 325 | T31: 325 | U31: 325 | V31: 325 | W31: 325 | X31: 325 | Y31: 325 | Z31: 325 | AA31: 325 | AB31: 325 | AC31: 325 | AD31: 325 | AE31: 325 | AF31: 325 | AG31: 325 | AH31: 325 | AI31: 325 | AJ31: 325 | AK31: 325 | AL31: 325
B32: Empleados asalariados | C32: =$D$11*C20 -> 0 | D32: =$D$11*D20 -> 0 | E32: =$D$11*E20 -> 0 | F32: =$D$11*F20 -> 0 | G32: =$D$11*G20 -> 750 | H32: =$D$11*H20 -> 750 | I32: =$D$11*I20 -> 750 | J32: =$D$11*J20 -> 750 | ... AL32: =$D$11*AL20 -> 1500
B33: SS asalariados | C33: =$F$11*C21 -> 0 | D33: =$F$11*D21 -> 0 | E33: =$F$11*E21 -> 0 | F33: =$F$11*F21 -> 0 | G33: =$F$11*G21 -> 225 | H33: =$F$11*H21 -> 225 | I33: =$F$11*I21 -> 225 | J33: =$F$11*J21 -> 225 | ... AL33: =$F$11*AL21 -> 450
B34: Costes de personal total € | C34: =SUM(C30:C33) -> 1825 | D34: =SUM(D30:D33) -> 1825 | E34: =SUM(E30:E33) -> 1825 | F34: =SUM(F30:F33) -> 1825 | G34: =SUM(G30:G33) -> 2800 | H34: =SUM(H30:H33) -> 2800 | I34: =SUM(I30:I33) -> 2800 | J34: =SUM(J30:J33) -> 2800 | ... AL34: =SUM(AL30:AL33) -> 3775

Sheet Precios y costes
B9: Precios y costes
B10: Servicio / categoría | C10: Ticket medio con IVA | D10: Ticket medio sin IVA | E10: Coste unitario estimado | F10: Margen unitario | G10: Coste % | H10: Margen %
B11: AgroPlaga App Base / PlagaScan gratuito | C11: 0 | D11: 0 | E11: 0 | F11: =D11-E11 -> 0
B12: AgroPlaga Premium / PlagaHub | C12: 145.2 | D12: 120 | E12: 30 | F12: =D12-E12 -> 90 | G12: =E12/D12 -> 0.25 | H12: =F12/D12 -> 0.75
B13: AgroClima IoT / Sensores y estación piloto | C13: 494.89 | D13: 409 | E13: 285 | F13: =D13-E13 -> 124 | G13: =E13/D13 -> 0.69682152 | H13: =F13/D13 -> 0.30317848
B14: Módulo Técnico / Panel Perito | C14: 566.28 | D14: 468 | E14: 96 | F14: =D14-E14 -> 372 | G14: =E14/D14 -> 0.20512821 | H14: =F14/D14 -> 0.79487179
B15: Enterprise Dashboard / NEXO Agro | C15: 3615.48 | D15: 2988 | E15: 840 | F15: =D15-E15 -> 2148 | G15: =E15/D15 -> 0.2811245 | H15: =F15/D15 -> 0.7188755

Sheet Ventas
B8: Ventas (unidades)
B9: Concepto | C9: Saldo
C10: Mes 1 | D10: Mes 2 | E10: Mes 3 | F10: Mes 4 | G10: Mes 5 | H10: Mes 6 | I10: Mes 7 | J10: Mes 8 | K10: Mes 9 | L10: Mes 10 | M10: Mes 11 | N10: Mes 12 | O10: Mes 13 | P10: Mes 14 | Q10: Mes 15 | R10: Mes 16 | S10: Mes 17 | T10: Mes 18 | U10: Mes 19 | V10: Mes 20 | W10: Mes 21 | X10: Mes 22 | Y10: Mes 23 | Z10: Mes 24 | AA10: Mes 25 | AB10: Mes 26 | AC10: Mes 27 | AD10: Mes 28 | AE10: Mes 29 | AF10: Mes 30 | AG10: Mes 31 | AH10: Mes 32 | AI10: Mes 33 | AJ10: Mes 34 | AK10: Mes 35 | AL10: Mes 36
B11: Servicios/productos | C11: ='Fuentes de financiación'!C30 -> 46266 | D11: =EDATE(C11,1) -> 46296 | E11: =EDATE(D11,1) -> 46327 | F11: =EDATE(E11,1) -> 46357 | G11: =EDATE(F11,1) -> 46388 | H11: =EDATE(G11,1) -> 46419 | I11: =EDATE(H11,1) -> 46447 | J11: =EDATE(I11,1) -> 46478 | K11: =EDATE(J11,1) -> 46508 | ... AL11: =EDATE(AK11,1) -> 47331
B12: ='Precios y costes'!B11 -> AgroPlaga App Base / PlagaScan gratuito | C12: 50 | D12: 60 | E12: 70 | F12: 80 | G12: 90 | H12: 100 | I12: 110 | J12: 120 | K12: 130 | L12: 120 | M12: 50 | N12: 20 | O12: 150 | P12: 170 | Q12: 190 | R12: 220 | S12: 250 | T12: 270 | U12: 290 | V12: 310 | W12: 320 | X12: 310 | Y12: 300 | Z12: 220 | AA12: 300 | AB12: 350 | AC12: 400 | AD12: 450 | AE12: 500 | AF12: 550 | AG12: 600 | AH12: 650 | AI12: 700 | AJ12: 750 | AK12: 450 | AL12: 300
B13: ='Precios y costes'!B12 -> AgroPlaga Premium / PlagaHub | C13: 0 | D13: 2 | E13: 4 | F13: 8 | G13: 12 | H13: 16 | I13: 18 | J13: 22 | K13: 28 | L13: 30 | M13: 25 | N13: 15 | O13: 10 | P13: 14 | Q13: 18 | R13: 24 | S13: 30 | T13: 36 | U13: 38 | V13: 42 | W13: 46 | X13: 40 | Y13: 33 | Z13: 19 | AA13: 35 | AB13: 44 | AC13: 53 | AD13: 64 | AE13: 75 | AF13: 86 | AG13: 88 | AH13: 97 | AI13: 96 | AJ13: 85 | AK13: 48 | AL13: 29
B14: ='Precios y costes'!B13 -> AgroClima IoT / Sensores y estación piloto | C14: 0 | D14: 0 | E14: 1 | F14: 1 | G14: 2 | H14: 2 | I14: 3 | J14: 3 | K14: 4 | L14: 4 | M14: 3 | N14: 2 | O14: 1 | P14: 2 | Q14: 3 | R14: 4 | S14: 5 | T14: 5 | U14: 6 | V14: 6 | W14: 6 | X14: 6 | Y14: 4 | Z14: 2 | AA14: 5 | AB14: 6 | AC14: 8 | AD14: 9 | AE14: 11 | AF14: 11 | AG14: 12 | AH14: 11 | AI14: 10 | AJ14: 9 | AK14: 5 | AL14: 3
B15: ='Precios y costes'!B14 -> Módulo Técnico / Panel Perito | C15: 0 | D15: 0 | E15: 0 | F15: 1 | G15: 2 | H15: 2 | I15: 2 | J15: 3 | K15: 3 | L15: 3 | M15: 2 | N15: 2 | O15: 1 | P15: 1 | Q15: 1 | R15: 3 | S15: 4 | T15: 4 | U15: 4 | V15: 4 | W15: 4 | X15: 4 | Y15: 3 | Z15: 2 | AA15: 3 | AB15: 4 | AC15: 4 | AD15: 7 | AE15: 8 | AF15: 8 | AG15: 8 | AH15: 8 | AI15: 7 | AJ15: 7 | AK15: 4 | AL15: 2
B16: ='Precios y costes'!B15 -> Enterprise Dashboard / NEXO Agro | C16: 0 | D16: 0 | E16: 0 | F16: 0 | G16: 1 | H16: 0 | I16: 1 | J16: 1 | K16: 1 | L16: 1 | M16: 0 | N16: 1 | O16: 0 | P16: 1 | Q16: 0 | R16: 1 | S16: 2 | T16: 0 | U16: 2 | V16: 1 | W16: 2 | X16: 1 | Y16: 1 | Z16: 1 | AA16: 1 | AB16: 2 | AC16: 1 | AD16: 3 | AE16: 4 | AF16: 2 | AG16: 4 | AH16: 3 | AI16: 4 | AJ16: 3 | AK16: 2 | AL16: 1
B17: Total | C17: =SUM(C12:C16) -> 50 | D17: =SUM(D12:D16) -> 62 | E17: =SUM(E12:E16) -> 75 | F17: =SUM(F12:F16) -> 90 | G17: =SUM(G12:G16) -> 107 | H17: =SUM(H12:H16) -> 120 | I17: =SUM(I12:I16) -> 134 | J17: =SUM(J12:J16) -> 149 | ... AL17: =SUM(AL12:AL16) -> 335
B20: Ventas (€)
B21: Concepto | C21: Saldo
C22: Mes 1 | D22: Mes 2 | E22: Mes 3 | F22: Mes 4 | G22: Mes 5 | H22: Mes 6 | I22: Mes 7 | J22: Mes 8 | K22: Mes 9 | L22: Mes 10 | M22: Mes 11 | N22: Mes 12 | O22: Mes 13 | P22: Mes 14 | Q22: Mes 15 | R22: Mes 16 | S22: Mes 17 | T22: Mes 18 | U22: Mes 19 | V22: Mes 20 | W22: Mes 21 | X22: Mes 22 | Y22: Mes 23 | Z22: Mes 24 | AA22: Mes 25 | AB22: Mes 26 | AC22: Mes 27 | AD22: Mes 28 | AE22: Mes 29 | AF22: Mes 30 | AG22: Mes 31 | AH22: Mes 32 | AI22: Mes 33 | AJ22: Mes 34 | AK22: Mes 35 | AL22: Mes 36
B23: Servicios/productos | C23: =C11 -> 46266 | D23: =D11 -> 46296 | E23: =E11 -> 46327 | F23: =F11 -> 46357 | G23: =G11 -> 46388 | H23: =H11 -> 46419 | I23: =I11 -> 46447 | J23: =J11 -> 46478 | ... AL23: =AL11 -> 47331
B24: =B12 -> AgroPlaga App Base / PlagaScan gratuito | C24: =C12*'Precios y costes'!$D11 -> 0 | D24: =D12*'Precios y costes'!$D11 -> 0 | E24: =E12*'Precios y costes'!$D11 -> 0 | F24: =F12*'Precios y costes'!$D11 -> 0 | G24: =G12*'Precios y costes'!$D11 -> 0 | H24: =H12*'Precios y costes'!$D11 -> 0 | I24: =I12*'Precios y costes'!$D11 -> 0 | J24: =J12*'Precios y costes'!$D11 -> 0 | ... AL24: =AL12*'Precios y costes'!$D11 -> 0
B25: =B13 -> AgroPlaga Premium / PlagaHub | C25: =C13*'Precios y costes'!$D12 -> 0 | D25: =D13*'Precios y costes'!$D12 -> 240 | E25: =E13*'Precios y costes'!$D12 -> 480 | F25: =F13*'Precios y costes'!$D12 -> 960 | G25: =G13*'Precios y costes'!$D12 -> 1440 | H25: =H13*'Precios y costes'!$D12 -> 1920 | I25: =I13*'Precios y costes'!$D12 -> 2160 | J25: =J13*'Precios y costes'!$D12 -> 2640 | ... AL25: =AL13*'Precios y costes'!$D12 -> 3480
B26: =B14 -> AgroClima IoT / Sensores y estación piloto | C26: =C14*'Precios y costes'!$D13 -> 0 | D26: =D14*'Precios y costes'!$D13 -> 0 | E26: =E14*'Precios y costes'!$D13 -> 409 | F26: =F14*'Precios y costes'!$D13 -> 409 | G26: =G14*'Precios y costes'!$D13 -> 818 | H26: =H14*'Precios y costes'!$D13 -> 818 | I26: =I14*'Precios y costes'!$D13 -> 1227 | J26: =J14*'Precios y costes'!$D13 -> 1227 | ... AL26: =AL14*'Precios y costes'!$D13 -> 1227
B27: =B15 -> Módulo Técnico / Panel Perito | C27: =C15*'Precios y costes'!$D14 -> 0 | D27: =D15*'Precios y costes'!$D14 -> 0 | E27: =E15*'Precios y costes'!$D14 -> 0 | F27: =F15*'Precios y costes'!$D14 -> 468 | G27: =G15*'Precios y costes'!$D14 -> 936 | H27: =H15*'Precios y costes'!$D14 -> 936 | I27: =I15*'Precios y costes'!$D14 -> 936 | J27: =J15*'Precios y costes'!$D14 -> 1404 | ... AL27: =AL15*'Precios y costes'!$D14 -> 936
B28: =B16 -> Enterprise Dashboard / NEXO Agro | C28: =C16*'Precios y costes'!$D15 -> 0 | D28: =D16*'Precios y costes'!$D15 -> 0 | E28: =E16*'Precios y costes'!$D15 -> 0 | F28: =F16*'Precios y costes'!$D15 -> 0 | G28: =G16*'Precios y costes'!$D15 -> 2988 | H28: =H16*'Precios y costes'!$D15 -> 0 | I28: =I16*'Precios y costes'!$D15 -> 2988 | J28: =J16*'Precios y costes'!$D15 -> 2988 | ... AL28: =AL16*'Precios y costes'!$D15 -> 2988
B29: Ventas totales € sin IVA | C29: =SUM(C24:C28) -> 0 | D29: =SUM(D24:D28) -> 240 | E29: =SUM(E24:E28) -> 889 | F29: =SUM(F24:F28) -> 1837 | G29: =SUM(G24:G28) -> 6182 | H29: =SUM(H24:H28) -> 3674 | I29: =SUM(I24:I28) -> 7311 | J29: =SUM(J24:J28) -> 8259 | ... AL29: =SUM(AL24:AL28) -> 8631
B30: Ventas totales € | C30: =C29*1.1 -> 0 | D30: =D29*1.21 -> 290.4 | E30: =E29*1.21 -> 1075.69 | F30: =F29*1.21 -> 2222.77 | G30: =G29*1.21 -> 7480.22 | H30: =H29*1.21 -> 4445.54 | I30: =I29*1.21 -> 8846.31 | J30: =J29*1.21 -> 9993.39 | K30: =K29*1.21 -> 11359.48 | ... AL30: =AL29*1.21 -> 10443.51

Sheet Costes
B8: Costes
B9: Concepto | C9: Saldo
C10: Mes 1 | D10: Mes 2 | E10: Mes 3 | F10: Mes 4 | G10: Mes 5 | H10: Mes 6 | I10: Mes 7 | J10: Mes 8 | K10: Mes 9 | L10: Mes 10 | M10: Mes 11 | N10: Mes 12 | O10: Mes 13 | P10: Mes 14 | Q10: Mes 15 | R10: Mes 16 | S10: Mes 17 | T10: Mes 18 | U10: Mes 19 | V10: Mes 20 | W10: Mes 21 | X10: Mes 22 | Y10: Mes 23 | Z10: Mes 24 | AA10: Mes 25 | AB10: Mes 26 | AC10: Mes 27 | AD10: Mes 28 | AE10: Mes 29 | AF10: Mes 30 | AG10: Mes 31 | AH10: Mes 32 | AI10: Mes 33 | AJ10: Mes 34 | AK10: Mes 35 | AL10: Mes 36
C11: =Ventas!C11 -> 46266 | D11: =Ventas!D11 -> 46296 | E11: =Ventas!E11 -> 46327 | F11: =Ventas!F11 -> 46357 | G11: =Ventas!G11 -> 46388 | H11: =Ventas!H11 -> 46419 | I11: =Ventas!I11 -> 46447 | J11: =Ventas!J11 -> 46478 | ... AL11: =Ventas!AL11 -> 47331
B12: =Ventas!B12 -> AgroPlaga App Base / PlagaScan gratuito | C12: =Ventas!C12*'Precios y costes'!$E11 -> 0 | D12: =Ventas!D12*'Precios y costes'!$E11 -> 0 | E12: =Ventas!E12*'Precios y costes'!$E11 -> 0 | F12: =Ventas!F12*'Precios y costes'!$E11 -> 0 | G12: =Ventas!G12*'Precios y costes'!$E11 -> 0 | H12: =Ventas!H12*'Precios y costes'!$E11 -> 0 | I12: =Ventas!I12*'Precios y costes'!$E11 -> 0 | J12: =Ventas!J12*'Precios y costes'!$E11 -> 0 | ... AL12: =Ventas!AL12*'Precios y costes'!$E11 -> 0
B13: =Ventas!B13 -> AgroPlaga Premium / PlagaHub | C13: =Ventas!C13*'Precios y costes'!$E12 -> 0 | D13: =Ventas!D13*'Precios y costes'!$E12 -> 60 | E13: =Ventas!E13*'Precios y costes'!$E12 -> 120 | F13: =Ventas!F13*'Precios y costes'!$E12 -> 240 | G13: =Ventas!G13*'Precios y costes'!$E12 -> 360 | H13: =Ventas!H13*'Precios y costes'!$E12 -> 480 | I13: =Ventas!I13*'Precios y costes'!$E12 -> 540 | J13: =Ventas!J13*'Precios y costes'!$E12 -> 660 | ... AL13: =Ventas!AL13*'Precios y costes'!$E12 -> 870
B14: =Ventas!B14 -> AgroClima IoT / Sensores y estación piloto | C14: =Ventas!C14*'Precios y costes'!$E13 -> 0 | D14: =Ventas!D14*'Precios y costes'!$E13 -> 0 | E14: =Ventas!E14*'Precios y costes'!$E13 -> 285 | F14: =Ventas!F14*'Precios y costes'!$E13 -> 285 | G14: =Ventas!G14*'Precios y costes'!$E13 -> 570 | H14: =Ventas!H14*'Precios y costes'!$E13 -> 570 | I14: =Ventas!I14*'Precios y costes'!$E13 -> 855 | J14: =Ventas!J14*'Precios y costes'!$E13 -> 855 | ... AL14: =Ventas!AL14*'Precios y costes'!$E13 -> 855
B15: =Ventas!B15 -> Módulo Técnico / Panel Perito | C15: =Ventas!C15*'Precios y costes'!$E14 -> 0 | D15: =Ventas!D15*'Precios y costes'!$E14 -> 0 | E15: =Ventas!E15*'Precios y costes'!$E14 -> 0 | F15: =Ventas!F15*'Precios y costes'!$E14 -> 96 | G15: =Ventas!G15*'Precios y costes'!$E14 -> 192 | H15: =Ventas!H15*'Precios y costes'!$E14 -> 192 | I15: =Ventas!I15*'Precios y costes'!$E14 -> 192 | J15: =Ventas!J15*'Precios y costes'!$E14 -> 288 | ... AL15: =Ventas!AL15*'Precios y costes'!$E14 -> 192
B16: =Ventas!B16 -> Enterprise Dashboard / NEXO Agro | C16: =Ventas!C16*'Precios y costes'!$E15 -> 0 | D16: =Ventas!D16*'Precios y costes'!$E15 -> 0 | E16: =Ventas!E16*'Precios y costes'!$E15 -> 0 | F16: =Ventas!F16*'Precios y costes'!$E15 -> 0 | G16: =Ventas!G16*'Precios y costes'!$E15 -> 840 | H16: =Ventas!H16*'Precios y costes'!$E15 -> 0 | I16: =Ventas!I16*'Precios y costes'!$E15 -> 840 | J16: =Ventas!J16*'Precios y costes'!$E15 -> 840 | ... AL16: =Ventas!AL16*'Precios y costes'!$E15 -> 840
B17: Compras | C17: =SUM(C12:C16) -> 0 | D17: =SUM(D12:D16) -> 60 | E17: =SUM(E12:E16) -> 405 | F17: =SUM(F12:F16) -> 621 | G17: =SUM(G12:G16) -> 1962 | H17: =SUM(H12:H16) -> 1242 | I17: =SUM(I12:I16) -> 2427 | J17: =SUM(J12:J16) -> 2643 | ... AL17: =SUM(AL12:AL16) -> 2757
B18: Variación existencias
B19: Alquileres | C19: ='Introducción de datos'!D32 -> 400 | D19: =C19 -> 400 | E19: =D19 -> 400 | F19: =E19 -> 400 | G19: =F19 -> 400 | H19: =G19 -> 400 | I19: =H19 -> 400 | J19: =I19 -> 400 | K19: =J19 -> 400 | ... AL19: =AK19 -> 400
B20: Suministros (agua, luz, gas,…) | C20: ='Introducción de datos'!D35 -> 90 | D20: =C20 -> 90 | E20: =D20 -> 90 | F20: =E20 -> 90 | G20: =F20 -> 90 | H20: =G20 -> 90 | I20: =H20 -> 90 | J20: =I20 -> 90 | K20: =J20 -> 90 | ... AL20: =AK20 -> 90
B21: Servicios externos | C21: ='Introducción de datos'!D38 -> 780 | D21: =C21 -> 780 | E21: =D21 -> 780 | F21: =E21 -> 780 | G21: =F21 -> 780 | H21: =G21 -> 780 | I21: =H21 -> 780 | J21: =I21 -> 780 | K21: =J21 -> 780 | ... AL21: =AK21 -> 780
B22: Tributos | C22: ='Introducción de datos'!D52 -> 50 | D22: =C22 -> 50 | E22: =D22 -> 50 | F22: =E22 -> 50 | G22: =F22 -> 50 | H22: =G22 -> 50 | I22: =H22 -> 50 | J22: =I22 -> 50 | K22: =J22 -> 50 | ... AL22: =AK22 -> 50
B23: Costes de personal | C23: =Personal!C34 -> 1825 | D23: =Personal!D34 -> 1825 | E23: =Personal!E34 -> 1825 | F23: =Personal!F34 -> 1825 | G23: =Personal!G34 -> 2800 | H23: =Personal!H34 -> 2800 | I23: =Personal!I34 -> 2800 | J23: =Personal!J34 -> 2800 | ... AL23: =Personal!AL34 -> 3775
B24: Costes financieros | C24: {=INDEX('Cuadro amortización crédito'!$D$13:$D$84,COLUMN(A1))} -> 172.5 | D24: {=INDEX('Cuadro amortización crédito'!$D$13:$D$84,COLUMN(B1))} -> 172.5 | E24: {=INDEX('Cuadro amortización crédito'!$D$13:$D$84,COLUMN(C1))} -> 172.5 | F24: {=INDEX('Cuadro amortización crédito'!$D$13:$D$84,COLUMN(D1))} -> 172.5 | G24: {=INDEX('Cuadro amortización crédito'!$D$13:$D$84,COLUMN(E1))} -> 172.5 | H24: {=INDEX('Cuadro amortización crédito'!$D$13:$D$84,COLUMN(F1))} -> 172.5 | I24: {=INDEX('Cuadro amortización crédito'!$D$13:$D$84,COLUMN(G1))} -> 172.5 | J24: {=INDEX('Cuadro amortización crédito'!$D$13:$D$84,COLUMN(H1))} -> 170.34359 | ... AL24: {=INDEX('Cuadro amortización crédito'!$D$13:$D$84,COLUMN(AJ1))} -> 104.65944
B25: Otros gastos | C25: ='Introducción de datos'!D45 -> 340 | D25: =C25 -> 340 | E25: =D25 -> 340 | F25: =E25 -> 340 | G25: =F25 -> 340 | H25: =G25 -> 340 | I25: =H25 -> 340 | J25: =I25 -> 340 | K25: =J25 -> 340 | ... AL25: =AK25 -> 340
B26: Amortizaciones | C26: ='Introducción de datos'!G8 -> 171.08333 | D26: =C26 -> 171.08333 | E26: =D26 -> 171.08333 | F26: =E26 -> 171.08333 | G26: =F26 -> 171.08333 | H26: =G26 -> 171.08333 | I26: =H26 -> 171.08333 | J26: =I26 -> 171.08333 | K26: =J26 -> 171.08333 | ... AL26: =AK26 -> 171.08333
B27: Provisiones
B28: Costes totales € | C28: =SUM(C17:C27) -> 3828.5833 | D28: =SUM(D17:D27) -> 3888.5833 | E28: =SUM(E17:E27) -> 4233.5833 | F28: =SUM(F17:F27) -> 4449.5833 | G28: =SUM(G17:G27) -> 6765.5833 | H28: =SUM(H17:H27) -> 6045.5833 | I28: =SUM(I17:I27) -> 7230.5833 | J28: =SUM(J17:J27) -> 7444.4269 | ... AL28: =SUM(AL17:AL27) -> 8467.7428

Sheet Cuenta de reslultados año1
B7: Cuenta de resultados año 1
B8: Concepto | C8: Saldo
C9: Mes 1 | D9: Mes 2 | E9: Mes 3 | F9: Mes 4 | G9: Mes 5 | H9: Mes 6 | I9: Mes 7 | J9: Mes 8 | K9: Mes 9 | L9: Mes 10 | M9: Mes 11 | N9: Mes 12 | O9: Total
B10: Ingresos | C10: =Costes!C11 -> 46266 | D10: =Costes!D11 -> 46296 | E10: =Costes!E11 -> 46327 | F10: =Costes!F11 -> 46357 | G10: =Costes!G11 -> 46388 | H10: =Costes!H11 -> 46419 | I10: =Costes!I11 -> 46447 | J10: =Costes!J11 -> 46478 | ... N10: =Costes!N11 -> 46600
B11: Ventas (clientes) | C11: =Ventas!C29 -> 0 | D11: =Ventas!D29 -> 240 | E11: =Ventas!E29 -> 889 | F11: =Ventas!F29 -> 1837 | G11: =Ventas!G29 -> 6182 | H11: =Ventas!H29 -> 3674 | I11: =Ventas!I29 -> 7311 | J11: =Ventas!J29 -> 8259 | ... N11: =Ventas!N29 -> 6542 | O11: =SUM(C11:N11) -> 59113
B12: Otros ingresos
B13: Ingresos financieros
B14: Total ingresos | C14: =SUM(C11:C13) -> 0 | D14: =SUM(D11:D13) -> 240 | E14: =SUM(E11:E13) -> 889 | F14: =SUM(F11:F13) -> 1837 | G14: =SUM(G11:G13) -> 6182 | H14: =SUM(H11:H13) -> 3674 | I14: =SUM(I11:I13) -> 7311 | J14: =SUM(J11:J13) -> 8259 | ... O14: =SUM(O11:O13) -> 59113
B15: Gastos
B16: Compras | C16: =Costes!C17 -> 0 | D16: =Costes!D17 -> 60 | E16: =Costes!E17 -> 405 | F16: =Costes!F17 -> 621 | G16: =Costes!G17 -> 1962 | H16: =Costes!H17 -> 1242 | I16: =Costes!I17 -> 2427 | J16: =Costes!J17 -> 2643 | ... N16: =Costes!N17 -> 2052 | O16: =SUM(C16:N16) -> 19485
B17: Variación de existencias | C17: =Costes!C18 -> 0 | D17: =Costes!D18 -> 0 | E17: =Costes!E18 -> 0 | F17: =Costes!F18 -> 0 | G17: =Costes!G18 -> 0 | H17: =Costes!H18 -> 0 | I17: =Costes!I18 -> 0 | J17: =Costes!J18 -> 0 | ... N17: =Costes!N18 -> 0 | O17: =SUM(C17:N17) -> 0
B18: Alquileres | C18: =Costes!C19 -> 400 | D18: =Costes!D19 -> 400 | E18: =Costes!E19 -> 400 | F18: =Costes!F19 -> 400 | G18: =Costes!G19 -> 400 | H18: =Costes!H19 -> 400 | I18: =Costes!I19 -> 400 | J18: =Costes!J19 -> 400 | ... N18: =Costes!N19 -> 400 | O18: =SUM(C18:N18) -> 4800
B19: Suministros (agua, luz, gas,…) | C19: =Costes!C20 -> 90 | D19: =Costes!D20 -> 90 | E19: =Costes!E20 -> 90 | F19: =Costes!F20 -> 90 | G19: =Costes!G20 -> 90 | H19: =Costes!H20 -> 90 | I19: =Costes!I20 -> 90 | J19: =Costes!J20 -> 90 | ... N19: =Costes!N20 -> 90 | O19: =SUM(C19:N19) -> 1080
B20: Servicios externos | C20: =Costes!C21 -> 780 | D20: =Costes!D21 -> 780 | E20: =Costes!E21 -> 780 | F20: =Costes!F21 -> 780 | G20: =Costes!G21 -> 780 | H20: =Costes!H21 -> 780 | I20: =Costes!I21 -> 780 | J20: =Costes!J21 -> 780 | ... N20: =Costes!N21 -> 780 | O20: =SUM(C20:N20) -> 9360
B21: Tributos | C21: =Costes!C22 -> 50 | D21: =Costes!D22 -> 50 | E21: =Costes!E22 -> 50 | F21: =Costes!F22 -> 50 | G21: =Costes!G22 -> 50 | H21: =Costes!H22 -> 50 | I21: =Costes!I22 -> 50 | J21: =Costes!J22 -> 50 | ... N21: =Costes!N22 -> 50 | O21: =SUM(C21:N21) -> 600
B22: Costes de personal | C22: =Costes!C23 -> 1825 | D22: =Costes!D23 -> 1825 | E22: =Costes!E23 -> 1825 | F22: =Costes!F23 -> 1825 | G22: =Costes!G23 -> 2800 | H22: =Costes!H23 -> 2800 | I22: =Costes!I23 -> 2800 | J22: =Costes!J23 -> 2800 | ... N22: =Costes!N23 -> 2800 | O22: =SUM(C22:N22) -> 29700
B23: Costes financieros | C23: =Costes!C24 -> 172.5 | D23: =Costes!D24 -> 172.5 | E23: =Costes!E24 -> 172.5 | F23: =Costes!F24 -> 172.5 | G23: =Costes!G24 -> 172.5 | H23: =Costes!H24 -> 172.5 | I23: =Costes!I24 -> 172.5 | J23: =Costes!J24 -> 170.34359 | ... N23: =Costes!N24 -> 161.59324 | O23: =SUM(C23:N23) -> 2037.4048
B24: Otros gastos | C24: =Costes!C25 -> 340 | D24: =Costes!D25 -> 340 | E24: =Costes!E25 -> 340 | F24: =Costes!F25 -> 340 | G24: =Costes!G25 -> 340 | H24: =Costes!H25 -> 340 | I24: =Costes!I25 -> 340 | J24: =Costes!J25 -> 340 | ... N24: =Costes!N25 -> 340 | O24: =SUM(C24:N24) -> 4080
B25: Amortizaciones | C25: =Costes!C26 -> 171.08333 | D25: =Costes!D26 -> 171.08333 | E25: =Costes!E26 -> 171.08333 | F25: =Costes!F26 -> 171.08333 | G25: =Costes!G26 -> 171.08333 | H25: =Costes!H26 -> 171.08333 | I25: =Costes!I26 -> 171.08333 | J25: =Costes!J26 -> 171.08333 | ... N25: =Costes!N26 -> 171.08333 | O25: =SUM(C25:N25) -> 2053
B26: Provisiones | C26: =Costes!C27 -> 0 | D26: =Costes!D27 -> 0 | E26: =Costes!E27 -> 0 | F26: =Costes!F27 -> 0 | G26: =Costes!G27 -> 0 | H26: =Costes!H27 -> 0 | I26: =Costes!I27 -> 0 | J26: =Costes!J27 -> 0 | ... N26: =Costes!N27 -> 0 | O26: =SUM(C26:N26) -> 0
B28: Total costes | C28: =SUM(C16:C27) -> 3828.5833 | D28: =SUM(D16:D27) -> 3888.5833 | E28: =SUM(E16:E27) -> 4233.5833 | F28: =SUM(F16:F27) -> 4449.5833 | G28: =SUM(G16:G27) -> 6765.5833 | H28: =SUM(H16:H27) -> 6045.5833 | I28: =SUM(I16:I27) -> 7230.5833 | J28: =SUM(J16:J27) -> 7444.4269 | ... O28: =SUM(O16:O27) -> 73195.405
B29: Beneficios /Perdidas | C29: =C14-C28 -> -3828.5833 | D29: =D14-D28 -> -3648.5833 | E29: =E14-E28 -> -3344.5833 | F29: =F14-F28 -> -2612.5833 | G29: =G14-G28 -> -583.58333 | H29: =H14-H28 -> -2371.5833 | I29: =I14-I28 -> 80.416667 | J29: =J14-J28 -> 814.57308 | ... O29: =O14-O28 -> -14082.405
N30: Impuestos | O30: =O29*0.1 -> -1408.2405
N31: Beneficios | O31: =O29-O30 -> -12674.164

Sheet Cuenta de resultados año2
B7: Cuenta de resultados año 2
B8: Concepto | C8: Saldo
C9: Mes 1 | D9: Mes 2 | E9: Mes 3 | F9: Mes 4 | G9: Mes 5 | H9: Mes 6 | I9: Mes 7 | J9: Mes 8 | K9: Mes 9 | L9: Mes 10 | M9: Mes 11 | N9: Mes 12 | O9: Total
B10: Ingresos | C10: =Costes!O11 -> 46631 | D10: =Costes!P11 -> 46661 | E10: =Costes!Q11 -> 46692 | F10: =Costes!R11 -> 46722 | G10: =Costes!S11 -> 46753 | H10: =Costes!T11 -> 46784 | I10: =Costes!U11 -> 46813 | J10: =Costes!V11 -> 46844 | ... N10: =Costes!Z11 -> 46966
B11: Ventas (clientes) | C11: =Ventas!O29 -> 2077 | D11: =Ventas!P29 -> 5954 | E11: =Ventas!Q29 -> 3855 | F11: =Ventas!R29 -> 8908 | G11: =Ventas!S29 -> 13493 | H11: =Ventas!T29 -> 8237 | I11: =Ventas!U29 -> 14862 | J11: =Ventas!V29 -> 12354 | ... N11: =Ventas!Z29 -> 7022 | O11: =SUM(C11:N11) -> 114686
B12: Otros ingresos | O12: 0
B13: Ingresos financieros | O13: 0
B14: Total ingresos | C14: =SUM(C11:C13) -> 2077 | D14: =SUM(D11:D13) -> 5954 | E14: =SUM(E11:E13) -> 3855 | F14: =SUM(F11:F13) -> 8908 | G14: =SUM(G11:G13) -> 13493 | H14: =SUM(H11:H13) -> 8237 | I14: =SUM(I11:I13) -> 14862 | J14: =SUM(J11:J13) -> 12354 | ... O14: =SUM(O11:O13) -> 114686
B15: Costes
B16: Compras | C16: =Costes!O17 -> 681 | D16: =Costes!P17 -> 1926 | E16: =Costes!Q17 -> 1491 | F16: =Costes!R17 -> 2988 | G16: =Costes!S17 -> 4389 | H16: =Costes!T17 -> 2889 | I16: =Costes!U17 -> 4914 | J16: =Costes!V17 -> 4194 | ... N16: =Costes!Z17 -> 2172 | O16: =SUM(C16:N16) -> 38190
B17: Variación de existencias | C17: =Costes!O18 -> 0 | D17: =Costes!P18 -> 0 | E17: =Costes!Q18 -> 0 | F17: =Costes!R18 -> 0 | G17: =Costes!S18 -> 0 | H17: =Costes!T18 -> 0 | I17: =Costes!U18 -> 0 | J17: =Costes!V18 -> 0 | ... N17: =Costes!Z18 -> 0 | O17: =SUM(C17:N17) -> 0
B18: Alquileres | C18: =Costes!O19 -> 400 | D18: =Costes!P19 -> 400 | E18: =Costes!Q19 -> 400 | F18: =Costes!R19 -> 400 | G18: =Costes!S19 -> 400 | H18: =Costes!T19 -> 400 | I18: =Costes!U19 -> 400 | J18: =Costes!V19 -> 400 | ... N18: =Costes!Z19 -> 400 | O18: =SUM(C18:N18) -> 4800
B19: Suministros (agua, luz, gas,…) | C19: =Costes!O20 -> 90 | D19: =Costes!P20 -> 90 | E19: =Costes!Q20 -> 90 | F19: =Costes!R20 -> 90 | G19: =Costes!S20 -> 90 | H19: =Costes!T20 -> 90 | I19: =Costes!U20 -> 90 | J19: =Costes!V20 -> 90 | ... N19: =Costes!Z20 -> 90 | O19: =SUM(C19:N19) -> 1080
B20: Servicios externos | C20: =Costes!O21 -> 780 | D20: =Costes!P21 -> 780 | E20: =Costes!Q21 -> 780 | F20: =Costes!R21 -> 780 | G20: =Costes!S21 -> 780 | H20: =Costes!T21 -> 780 | I20: =Costes!U21 -> 780 | J20: =Costes!V21 -> 780 | ... N20: =Costes!Z21 -> 780 | O20: =SUM(C20:N20) -> 9360
B21: Tributos | C21: =Costes!O22 -> 50 | D21: =Costes!P22 -> 50 | E21: =Costes!Q22 -> 50 | F21: =Costes!R22 -> 50 | G21: =Costes!S22 -> 50 | H21: =Costes!T22 -> 50 | I21: =Costes!U22 -> 50 | J21: =Costes!V22 -> 50 | ... N21: =Costes!Z22 -> 50 | O21: =SUM(C21:N21) -> 600
B22: Costes de personal | C22: =Costes!O23 -> 2800 | D22: =Costes!P23 -> 2800 | E22: =Costes!Q23 -> 2800 | F22: =Costes!R23 -> 2800 | G22: =Costes!S23 -> 3775 | H22: =Costes!T23 -> 3775 | I22: =Costes!U23 -> 3775 | J22: =Costes!V23 -> 3775 | ... N22: =Costes!Z23 -> 3775 | O22: =SUM(C22:N22) -> 41400
B23: Costes financieros | C23: =Costes!O24 -> 159.37412 | D23: =Costes!P24 -> 157.14224 | E23: =Costes!Q24 -> 154.89752 | F23: =Costes!R24 -> 152.6399 | G23: =Costes!S24 -> 150.36929 | H23: =Costes!T24 -> 148.08563 | I23: =Costes!U24 -> 145.78884 | J23: =Costes!V24 -> 143.47884 | ... N23: =Costes!Z24 -> 134.10525 | O23: =SUM(C23:N23) -> 1762.3249
B24: Otros gastos | C24: =Costes!O25 -> 340 | D24: =Costes!P25 -> 340 | E24: =Costes!Q25 -> 340 | F24: =Costes!R25 -> 340 | G24: =Costes!S25 -> 340 | H24: =Costes!T25 -> 340 | I24: =Costes!U25 -> 340 | J24: =Costes!V25 -> 340 | ... N24: =Costes!Z25 -> 340 | O24: =SUM(C24:N24) -> 4080
B25: Amortizaciones | C25: =Costes!O26 -> 171.08333 | D25: =Costes!P26 -> 171.08333 | E25: =Costes!Q26 -> 171.08333 | F25: =Costes!R26 -> 171.08333 | G25: =Costes!S26 -> 171.08333 | H25: =Costes!T26 -> 171.08333 | I25: =Costes!U26 -> 171.08333 | J25: =Costes!V26 -> 171.08333 | ... N25: =Costes!Z26 -> 171.08333 | O25: =SUM(C25:N25) -> 2053
B26: Provisiones | C26: =Costes!O27 -> 0 | D26: =Costes!P27 -> 0 | E26: =Costes!Q27 -> 0 | F26: =Costes!R27 -> 0 | G26: =Costes!S27 -> 0 | H26: =Costes!T27 -> 0 | I26: =Costes!U27 -> 0 | J26: =Costes!V27 -> 0 | ... N26: =Costes!Z27 -> 0 | O26: =SUM(C26:N26) -> 0
B28: Total costes | C28: =SUM(C16:C27) -> 5471.4575 | D28: =SUM(D16:D27) -> 6714.2256 | E28: =SUM(E16:E27) -> 6276.9809 | F28: =SUM(F16:F27) -> 7771.7232 | G28: =SUM(G16:G27) -> 10145.453 | H28: =SUM(H16:H27) -> 8643.169 | I28: =SUM(I16:I27) -> 10665.872 | J28: =SUM(J16:J27) -> 9943.5622 | ... O28: =SUM(O16:O27) -> 103325.32
B29: Beneficios /Perdidas | C29: =C14-C28 -> -3394.4575 | D29: =D14-D28 -> -760.22557 | E29: =E14-E28 -> -2421.9809 | F29: =F14-F28 -> 1136.2768 | G29: =G14-G28 -> 3347.5474 | H29: =H14-H28 -> -406.16896 | I29: =I14-I28 -> 4196.1278 | J29: =J14-J28 -> 2410.4378 | ... O29: =O14-O28 -> 11360.675
N30: Impuestos | O30: =O29*0.1 -> 1136.0675
N31: Beneficios | O31: =O29-O30 -> 10224.608

Sheet Cuenta resultados año3
B7: Cuenta de resultados año 3
B8: Concepto | C8: Saldo
C9: Mes 1 | D9: Mes 2 | E9: Mes 3 | F9: Mes 4 | G9: Mes 5 | H9: Mes 6 | I9: Mes 7 | J9: Mes 8 | K9: Mes 9 | L9: Mes 10 | M9: Mes 11 | N9: Mes 12 | O9: Total
B10: Ingresos | C10: =Costes!AA11 -> 46997 | D10: =Costes!AB11 -> 47027 | E10: =Costes!AC11 -> 47058 | F10: =Costes!AD11 -> 47088 | G10: =Costes!AE11 -> 47119 | H10: =Costes!AF11 -> 47150 | I10: =Costes!AG11 -> 47178 | J10: =Costes!AH11 -> 47209 | ... N10: =Costes!AL11 -> 47331
B11: Ventas (clientes) | C11: =Ventas!AA29 -> 10637 | D11: =Ventas!AB29 -> 15582 | E11: =Ventas!AC29 -> 14492 | F11: =Ventas!AD29 -> 23601 | G11: =Ventas!AE29 -> 29195 | H11: =Ventas!AF29 -> 24539 | I11: =Ventas!AG29 -> 31164 | J11: =Ventas!AH29 -> 28847 | ... N11: =Ventas!AL29 -> 8631 | O11: =SUM(C11:N11) -> 259300
B12: Otros ingresos | O12: 0
B13: Ingresos financieros | O13: 0
B14: Total ingresos | C14: =SUM(C11:C13) -> 10637 | D14: =SUM(D11:D13) -> 15582 | E14: =SUM(E11:E13) -> 14492 | F14: =SUM(F11:F13) -> 23601 | G14: =SUM(G11:G13) -> 29195 | H14: =SUM(H11:H13) -> 24539 | I14: =SUM(I11:I13) -> 31164 | J14: =SUM(J11:J13) -> 28847 | ... O14: =SUM(O11:O13) -> 259300
B15: Costes
B16: Compras | C16: =Costes!AA17 -> 3603 | D16: =Costes!AB17 -> 5094 | E16: =Costes!AC17 -> 5094 | F16: =Costes!AD17 -> 7677 | G16: =Costes!AE17 -> 9513 | H16: =Costes!AF17 -> 8163 | I16: =Costes!AG17 -> 10188 | J16: =Costes!AH17 -> 9333 | ... N16: =Costes!AL17 -> 2757 | O16: =SUM(C16:N16) -> 84420
B17: Variación de existencias | C17: =Costes!AA18 -> 0 | D17: =Costes!AB18 -> 0 | E17: =Costes!AC18 -> 0 | F17: =Costes!AD18 -> 0 | G17: =Costes!AE18 -> 0 | H17: =Costes!AF18 -> 0 | I17: =Costes!AG18 -> 0 | J17: =Costes!AH18 -> 0 | ... N17: =Costes!AL18 -> 0 | O17: =SUM(C17:N17) -> 0
B18: Alquileres | C18: =Costes!AA19 -> 400 | D18: =Costes!AB19 -> 400 | E18: =Costes!AC19 -> 400 | F18: =Costes!AD19 -> 400 | G18: =Costes!AE19 -> 400 | H18: =Costes!AF19 -> 400 | I18: =Costes!AG19 -> 400 | J18: =Costes!AH19 -> 400 | ... N18: =Costes!AL19 -> 400 | O18: =SUM(C18:N18) -> 4800
B19: Suministros (agua, luz, gas,…) | C19: =Costes!AA20 -> 90 | D19: =Costes!AB20 -> 90 | E19: =Costes!AC20 -> 90 | F19: =Costes!AD20 -> 90 | G19: =Costes!AE20 -> 90 | H19: =Costes!AF20 -> 90 | I19: =Costes!AG20 -> 90 | J19: =Costes!AH20 -> 90 | ... N19: =Costes!AL20 -> 90 | O19: =SUM(C19:N19) -> 1080
B20: Servicios externos | C20: =Costes!AA21 -> 780 | D20: =Costes!AB21 -> 780 | E20: =Costes!AC21 -> 780 | F20: =Costes!AD21 -> 780 | G20: =Costes!AE21 -> 780 | H20: =Costes!AF21 -> 780 | I20: =Costes!AG21 -> 780 | J20: =Costes!AH21 -> 780 | ... N20: =Costes!AL21 -> 780 | O20: =SUM(C20:N20) -> 9360
B21: Tributos | C21: =Costes!AA22 -> 50 | D21: =Costes!AB22 -> 50 | E21: =Costes!AC22 -> 50 | F21: =Costes!AD22 -> 50 | G21: =Costes!AE22 -> 50 | H21: =Costes!AF22 -> 50 | I21: =Costes!AG22 -> 50 | J21: =Costes!AH22 -> 50 | ... N21: =Costes!AL22 -> 50 | O21: =SUM(C21:N21) -> 600
B22: Costes de personal | C22: =Costes!AA23 -> 3775 | D22: =Costes!AB23 -> 3775 | E22: =Costes!AC23 -> 3775 | F22: =Costes!AD23 -> 3775 | G22: =Costes!AE23 -> 3775 | H22: =Costes!AF23 -> 3775 | I22: =Costes!AG23 -> 3775 | J22: =Costes!AH23 -> 3775 | ... N22: =Costes!AL23 -> 3775 | O22: =SUM(C22:N22) -> 45300
B23: Costes financieros | C23: =Costes!AA24 -> 131.72807 | D23: =Costes!AB24 -> 129.33722 | E23: =Costes!AC24 -> 126.93263 | F23: =Costes!AD24 -> 124.51421 | G23: =Costes!AE24 -> 122.08188 | H23: =Costes!AF24 -> 119.63556 | I23: =Costes!AG24 -> 117.17518 | J23: =Costes!AH24 -> 114.70066 | ... N23: =Costes!AL24 -> 104.65944 | O23: =SUM(C23:N23) -> 1419.877
B24: Otros gastos | C24: =Costes!AA25 -> 340 | D24: =Costes!AB25 -> 340 | E24: =Costes!AC25 -> 340 | F24: =Costes!AD25 -> 340 | G24: =Costes!AE25 -> 340 | H24: =Costes!AF25 -> 340 | I24: =Costes!AG25 -> 340 | J24: =Costes!AH25 -> 340 | ... N24: =Costes!AL25 -> 340 | O24: =SUM(C24:N24) -> 4080
B25: Amortizaciones | C25: =Costes!AA26 -> 171.08333 | D25: =Costes!AB26 -> 171.08333 | E25: =Costes!AC26 -> 171.08333 | F25: =Costes!AD26 -> 171.08333 | G25: =Costes!AE26 -> 171.08333 | H25: =Costes!AF26 -> 171.08333 | I25: =Costes!AG26 -> 171.08333 | J25: =Costes!AH26 -> 171.08333 | ... N25: =Costes!AL26 -> 171.08333 | O25: =SUM(C25:N25) -> 2053
B26: Provisiones | C26: =Costes!AA27 -> 0 | D26: =Costes!AB27 -> 0 | E26: =Costes!AC27 -> 0 | F26: =Costes!AD27 -> 0 | G26: =Costes!AE27 -> 0 | H26: =Costes!AF27 -> 0 | I26: =Costes!AG27 -> 0 | J26: =Costes!AH27 -> 0 | ... N26: =Costes!AL27 -> 0 | O26: =SUM(C26:N26) -> 0
B28: Total costes | C28: =SUM(C16:C26) -> 9340.8114 | D28: =SUM(D16:D26) -> 10829.421 | E28: =SUM(E16:E26) -> 10827.016 | F28: =SUM(F16:F26) -> 13407.598 | G28: =SUM(G16:G26) -> 15241.165 | H28: =SUM(H16:H26) -> 13888.719 | I28: =SUM(I16:I26) -> 15911.259 | J28: =SUM(J16:J26) -> 15053.784 | ... O28: =SUM(O16:O26) -> 153112.88
B29: Beneficios /Perdidas | C29: =C14-C28 -> 1296.1886 | D29: =D14-D28 -> 4752.5794 | E29: =E14-E28 -> 3664.984 | F29: =F14-F28 -> 10193.402 | G29: =G14-G28 -> 13953.835 | H29: =H14-H28 -> 10650.281 | I29: =I14-I28 -> 15252.741 | J29: =J14-J28 -> 13793.216 | ... O29: =O14-O28 -> 106187.12
N30: Impuestos | O30: =O29*0.1 -> 10618.712
N31: Beneficios | O31: =O29-O30 -> 95568.411

Sheet Plan de Tesorería
B5: Previsión de Tesorería año 1
B6: Concepto | C6: Saldo
C7: Mes 1 | D7: Mes 2 | E7: Mes 3 | F7: Mes 4 | G7: Mes 5 | H7: Mes 6 | I7: Mes 7 | J7: Mes 8 | K7: Mes 9 | L7: Mes 10 | M7: Mes 11 | N7: Mes 12 | O7: Total
B8: Cobros | C8: ='Cuenta de reslultados año1'!C10 -> 46266 | D8: ='Cuenta de reslultados año1'!D10 -> 46296 | E8: ='Cuenta de reslultados año1'!E10 -> 46327 | F8: ='Cuenta de reslultados año1'!F10 -> 46357 | G8: ='Cuenta de reslultados año1'!G10 -> 46388 | H8: ='Cuenta de reslultados año1'!H10 -> 46419 | I8: ='Cuenta de reslultados año1'!I10 -> 46447 | J8: ='Cuenta de reslultados año1'!J10 -> 46478 | ... N8: ='Cuenta de reslultados año1'!N10 -> 46600
B9: Cobros por ventas | C9: =Ventas!C30 -> 0 | D9: =Ventas!D30 -> 290.4 | E9: =Ventas!E30 -> 1075.69 | F9: =Ventas!F30 -> 2222.77 | G9: =Ventas!G30 -> 7480.22 | H9: =Ventas!H30 -> 4445.54 | I9: =Ventas!I30 -> 8846.31 | J9: =Ventas!J30 -> 9993.39 | ... N9: =Ventas!N30 -> 7915.82 | O9: =SUM(C9:N9) -> 71526.73
B10: Otros cobros | O10: =SUM(C10:N10) -> 0
B11: Total Cobros | C11: =SUM(C9:C10) -> 0 | D11: =SUM(D9:D10) -> 290.4 | E11: =SUM(E9:E10) -> 1075.69 | F11: =SUM(F9:F10) -> 2222.77 | G11: =SUM(G9:G10) -> 7480.22 | H11: =SUM(H9:H10) -> 4445.54 | I11: =SUM(I9:I10) -> 8846.31 | J11: =SUM(J9:J10) -> 9993.39 | ... N11: =SUM(N9:N10) -> 7915.82 | O11: =SUM(O1:O10) -> 71526.73
B12: Pagos
B13: Compras | C13: =Costes!C17*1.1 -> 0 | D13: =Costes!D17*1.1 -> 66 | E13: =Costes!E17*1.1 -> 445.5 | F13: =Costes!F17*1.1 -> 683.1 | G13: =Costes!G17*1.1 -> 2158.2 | H13: =Costes!H17*1.1 -> 1366.2 | I13: =Costes!I17*1.1 -> 2669.7 | J13: =Costes!J17*1.1 -> 2907.3 | ... N13: =Costes!N17*1.1 -> 2257.2 | O13: =SUM(C13:N13) -> 21433.5
B14: Alquileres | C14: =Costes!C19*1.21 -> 484 | D14: =Costes!D19*1.21 -> 484 | E14: =Costes!E19*1.21 -> 484 | F14: =Costes!F19*1.21 -> 484 | G14: =Costes!G19*1.21 -> 484 | H14: =Costes!H19*1.21 -> 484 | I14: =Costes!I19*1.21 -> 484 | J14: =Costes!J19*1.21 -> 484 | ... N14: =Costes!N19*1.21 -> 484 | O14: =SUM(C14:N14) -> 5808
B15: Suministros | C15: =Costes!C20*1.21 -> 108.9 | D15: =Costes!D20*1.21 -> 108.9 | E15: =Costes!E20*1.21 -> 108.9 | F15: =Costes!F20*1.21 -> 108.9 | G15: =Costes!G20*1.21 -> 108.9 | H15: =Costes!H20*1.21 -> 108.9 | I15: =Costes!I20*1.21 -> 108.9 | J15: =Costes!J20*1.21 -> 108.9 | ... N15: =Costes!N20*1.21 -> 108.9 | O15: =SUM(C15:N15) -> 1306.8
B16: Gastos exteriores | C16: =Costes!C21*1.21 -> 943.8 | D16: =Costes!D21*1.21 -> 943.8 | E16: =Costes!E21*1.21 -> 943.8 | F16: =Costes!F21*1.21 -> 943.8 | G16: =Costes!G21*1.21 -> 943.8 | H16: =Costes!H21*1.21 -> 943.8 | I16: =Costes!I21*1.21 -> 943.8 | J16: =Costes!J21*1.21 -> 943.8 | ... N16: =Costes!N21*1.21 -> 943.8 | O16: =SUM(C16:N16) -> 11325.6
B17: Tributos | C17: =Costes!C22 -> 50 | D17: =Costes!D22 -> 50 | E17: =Costes!E22 -> 50 | F17: =Costes!F22 -> 50 | G17: =Costes!G22 -> 50 | H17: =Costes!H22 -> 50 | I17: =Costes!I22 -> 50 | J17: =Costes!J22 -> 50 | ... N17: =Costes!N22 -> 50 | O17: =SUM(C17:N17) -> 600
B18: Costes de personal | C18: =Costes!C23 -> 1825 | D18: =Costes!D23 -> 1825 | E18: =Costes!E23 -> 1825 | F18: =Costes!F23 -> 1825 | G18: =Costes!G23 -> 2800 | H18: =Costes!H23 -> 2800 | I18: =Costes!I23 -> 2800 | J18: =Costes!J23 -> 2800 | ... N18: =Costes!N23 -> 2800 | O18: =SUM(C18:N18) -> 29700
B19: Otros gastos | C19: =Costes!C25 -> 340 | D19: =Costes!D25 -> 340 | E19: =Costes!E25 -> 340 | F19: =Costes!F25 -> 340 | G19: =Costes!G25 -> 340 | H19: =Costes!H25 -> 340 | I19: =Costes!I25 -> 340 | J19: =Costes!J25 -> 340 | ... N19: =Costes!N25 -> 340 | O19: =SUM(C19:N19) -> 4080
B20: Cuota microcrédito | C20: {=INDEX('Cuadro amortización crédito'!$C$13:$C$84,COLUMN(A1))} -> 172.5 | D20: {=INDEX('Cuadro amortización crédito'!$C$13:$C$84,COLUMN(B1))} -> 172.5 | E20: {=INDEX('Cuadro amortización crédito'!$C$13:$C$84,COLUMN(C1))} -> 172.5 | F20: {=INDEX('Cuadro amortización crédito'!$C$13:$C$84,COLUMN(D1))} -> 172.5 | G20: {=INDEX('Cuadro amortización crédito'!$C$13:$C$84,COLUMN(E1))} -> 172.5 | H20: {=INDEX('Cuadro amortización crédito'!$C$13:$C$84,COLUMN(F1))} -> 172.5 | I20: {=INDEX('Cuadro amortización crédito'!$C$13:$C$84,COLUMN(G1))} -> 547.52777 | J20: {=INDEX('Cuadro amortización crédito'!$C$13:$C$84,COLUMN(H1))} -> 547.52777 | ... N20: {=INDEX('Cuadro amortización crédito'!$C$13:$C$84,COLUMN(L1))} -> 547.52777 | O20: =SUM(C20:N20) -> 4320.1666
B21: Liquidación IVA | F21: -660.66 | I21: 852.18 | L21: 2723.7 | O21: =SUM(C21:N21) -> 2915.22
O22: =SUM(C22:N22) -> 0
B23: Total Pagos | C23: =SUM(C13:C22) -> 3924.2 | D23: =SUM(D13:D22) -> 3990.2 | E23: =SUM(E13:E22) -> 4369.7 | F23: =SUM(F13:F22) -> 3946.64 | G23: =SUM(G13:G22) -> 7057.4 | H23: =SUM(H13:H22) -> 6265.4 | I23: =SUM(I13:I22) -> 8796.1078 | J23: =SUM(J13:J22) -> 8181.5278 | ... O23: =SUM(O13:O22) -> 81489.287
B24: Saldo Mes | C24: =C11-C23 -> -3924.2 | D24: =D11-D23 -> -3699.8 | E24: =E11-E23 -> -3294.01 | F24: =F11-F23 -> -1723.87 | G24: =G11-G23 -> 422.82 | H24: =H11-H23 -> -1819.86 | I24: =I11-I23 -> 50.202226 | J24: =J11-J23 -> 1811.8622 | ... N24: =N11-N23 -> 384.39223 | O24: =SUM(C24:N24) -> -9962.5566
B25: Saldo Acumulado | C25: =C24 -> -3924.2 | D25: =C25+D24 -> -7624 | E25: =D25+E24 -> -10918.01 | F25: =E25+F24 -> -12641.88 | G25: =F25+G24 -> -12219.06 | H25: =G25+H24 -> -14038.92 | I25: =H25+I24 -> -13988.718 | J25: =I25+J24 -> -12176.856 | K25: =J25+K24 -> -9510.4033 | ... N25: =M25+N24 -> -9962.5566

Sheet Balance
B4: Balance de situación
B5: Activo | F5: Pasivo
B6: Cuenta | C6: Año 1 | D6: Año 2 | E6: Año 3 | F6: Cuenta | G6: Año 1 | H6: Año 2 | I6: Año 3
B7: INMOVILIZADO | F7: NO EXIGIBLE
F8: Capital social
B9: Gastos de constitución | F9: Reserva Estatutaria
B10: INMATERIAL | F10: Reserva Legal
B11: Derechos de traspaso | F11: Pérdidas y ganancias
B12: Aplicaciones informáticas
B13: Amortización acumulada inmovilizado
B14: MATERIAL
B15: Construcciones | D15: =C15 -> 0 | E15: =D15 -> 0
B16: Maquinaria
B17: Otras instalaciones | F17: EXIGIBLE A LARGO PLAZO
B18: Mobiliario | F18: Deudas a largo plazo con entidades de crédito
B19: Equipos de proceso información | F19: Proveedores
B20: Elementos de transporte | F20: Efectos a pagar
B21: Otros inmovilizados
B22: Amortizacion acumulada inmovilizado
B23: CIRCULANTE | F23: EXIGIBLE A CORTO PLAZO
B24: Existencias | F24: Proveedores
B25: Anticipos proveedores | F25: Efectos a pagar
B26: Clientes | F26: Acreedores
B27: Efectos a cobrar | F27: Anticipos a clientes
B28: Deudores varios | F28: Remuneraciones pendientes de pago
B29: Hacienda Pública deudora | F29: Hacienda Pública Acreedora
B30: Caja en efectivo | F30: Organismos de Seguridad Social
B31: Bancos | F31: Deudas a corto plazo con entidades de crédito
B32: SUMA TOTAL ACTIVO | C32: =SUM(C24:C31,C15:C22,C11:C13,C8:C9) -> 0 | D32: =SUM(D24:D31,D15:D22,D11:D13,D8:D9) -> 0 | E32: =SUM(E24:E31,E15:E22,E11:E13,E8:E9) -> 0 | F32: SUMA TOTAL PASIVO | G32: =SUM(G24:G31,G15:G22,G11:G13,G8:G9) -> 0 | H32: =SUM(H24:H31,H15:H22,H11:H13,H8:H9) -> 0 | I32: =SUM(I24:I31,I15:I22,I11:I13,I8:I9) -> 0

Sheet Ratios
B4: Ratios
C5: Total año
B6: Punto de equilibrio | C6: =C15 -> 80119.692
B7: Alquiler/Ventas | C7: =C22 -> 0
B8: Coste del traspaso | C8: ='[1]Introducción de datos'!C16 -> 0
B10: Alquiler | C10: ='Introducción de datos'!D33 -> 0
B13: Cálculo del punto de equilibrio
B15: Punto Muerto = Coste Fijo / % Margen Bruto | C15: =C16/C18 -> 80119.692
B16: Costes fijos | C16: =SUM('Cuenta de reslultados año1'!O18:O27) -> 53710.405
B17: Margen bruto | C17: ='Cuenta de reslultados año1'!O11-'Cuenta de reslultados año1'!O16 -> 39628
B18: % Margen Bruto | C18: =C17/'Cuenta de reslultados año1'!O11 -> 0.67037707
B20: Alquiler/Ventas
B22: Alquiler/Ventas: Importe mensual del alquiler/Ventas mensuales ponderadas | C22: ='Introducción de datos'!D33/AVERAGE(Ventas!C29:AL29) -> 0
B25: Coste del traspaso:
B27: CT: Traspaso/ (Retribución del promotor + Beneficio) | C27: ='[1]Introducción de datos'!C16/(SUM([1]Personal!C28:AL29)+'[1]Cuenta de reslultados año1'!O29) -> 0
